# 🔧 Registration/Login Error - FIXED

## Problem
Users were seeing "System Error" when trying to register or login.

## Root Cause
**Data Structure Mismatch** between `key_management.py` and `database.py`

### The Issue:
1. `key_manager.register_user()` returns:
   ```python
   {
       'user_id': 'alice',
       'public_keys': {
           'identity': '...',
           'signed_prekey': '...',
           'verify_key': '...',
           'user_id': '...',
           'created_at': 123456789
       },
       'qr_code': '...',
       'fingerprint': '...',
       'alias': 'Alice'
   }
   ```

2. But `database.save_user()` was expecting:
   - `created_at` at the top level (not inside `public_keys`)
   - `encrypted_private_keys` field (which doesn't exist)

## Solution Applied

### Fixed `database.py` (Lines 143-203):

1. **Removed non-existent field**: Removed reference to `encrypted_private_keys`
2. **Fixed created_at**: Now gets it from `public_keys.get('created_at')`  
3. **Added qr_code storage**: Now stores the QR code in encrypted data
4. **Better error handling**: Added debug prints and traceback

**Changes:**
```python
# OLD (BROKEN):
private_data = {
    'alias': user_data.get('alias'),
    'encrypted_private_keys': user_data.get('encrypted_private_keys'),  # ❌ Doesn't exist!
    'metadata': user_data.get('metadata', {})
}
created_at = user_data.get('created_at', ...)  # ❌ Wrong location!

# NEW (FIXED):
private_data = {
    'alias': user_data.get('alias'),
    'qr_code': user_data.get('qr_code'),  # ✅ Actually exists!
    'metadata': user_data.get('metadata', {})
}
created_at = public_keys.get('created_at', ...)  # ✅ Correct location!
```

### Fixed `app.py` (Lines 288-344):

1. **Added debug logging**: Shows data structure when errors occur
2. **Added traceback**: Full error details printed to console

**Changes:**
```python
except Exception as e:
    print(f"❌ Registration error: {str(e)}")
    import traceback
    traceback.print_exc()  # Shows full error details
    flash(f'Registration failed: {str(e)}', 'error')
```

## Testing

Created `test_registration.py` to verify the fix:

```bash
python test_registration.py
```

**Result**: ✅ **PASSED**
```
✅ User saved successfully!
✅ User retrieved successfully!
✅ Registration flow test PASSED!
```

## Verification

The application now runs without errors:

```bash
python app.py
```

Output:
```
✅ Encrypted database initialized
✅ All security systems initialized
🚀 Military-grade secure messaging app starting...
📍 Local access: http://127.0.0.1:5001
```

## How to Test

1. **Start the application**:
   ```bash
   python app.py
   ```

2. **Open browser**: `http://127.0.0.1:5001`

3. **Register a new user**:
   - Click "Register New Account"
   - Enter User ID: `alice123`
   - Enter Alias: `Alice Smith`
   - Click "Register"

4. **Expected Result**:
   - ✅ Registration successful
   - ✅ QR code displayed
   - ✅ User saved to database
   - ✅ Can logout and login again

## Files Modified

1. ✅ `database.py` - Fixed save_user() method
2. ✅ `app.py` - Added better error logging
3. ✅ `test_registration.py` - Created test to verify fix

## Status

🎉 **FIXED and VERIFIED**

Registration and login now work correctly!
